<?xml version="1.0" ?>
<!-- =================================================================================== -->
<!-- |    This document was autogenerated by xacro from frcrobot.xacro                 | -->
<!-- |    EDITING THIS FILE BY HAND IS NOT RECOMMENDED                                 | -->
<!-- =================================================================================== -->
<!-- Simple swerve base -->
<robot name="frcrobot">
  <link name="base_plate">
    <visual>
      <geometry>
        <box size="0.75 0.75 0.15"/>
      </geometry>
      <material name="blue">
        <color rgba="0 0 1 1"/>
      </material>
    </visual>
    <collision>
      <geometry>
        <box size="0.75 0.75 0.15"/>
      </geometry>
    </collision>
    <inertial>
      <mass value="10.0"/>
      <inertia ixx="1.0" ixy="0.0" ixz="0.0" iyy="1.0" iyz="0.0" izz="1.0"/>
    </inertial>
  </link>
  <joint name="base_plate_to_base_link" type="fixed">
    <parent link="base_link"/>
    <child link="base_plate"/>
    <origin rpy="0 0 0" xyz="0 0 0.14250000000000002"/>
  </joint>
  <!--	<xacro:property name="elevator_height" value="1.1" /> -->
  <!--	<xacro:property name="elevator_width"  value="${base_width / 2.}" /> -->
  <!--	<link name="elevator_plate">-->
  <!--		<visual>-->
  <!--			<geometry>-->
  <!--				<box size="${elevator_width} 0.05 ${elevator_height}"/>-->
  <!--			</geometry>-->
  <!--			<material name="yellow">-->
  <!--				<color rgba="1 1 0 1"/>-->
  <!--			</material>-->
  <!--		</visual>-->
  <!--	</link>-->
  <!--	<joint name="elevator_plate_to_base_link" type="fixed">-->
  <!--		<parent link="base_plate"/>-->
  <!--		<child link="elevator_plate"/>-->
  <!--		<origin xyz="-0.25 0 ${elevator_height/2 + base_height/2}" rpy="0 0 ${pi/2}"/>-->
  <!--	</joint>-->
  <link name="lf_angle">
    <visual>
      <geometry>
        <box size="0.075 0.075 0.075"/>
      </geometry>
      <origin rpy="0 0 0" xyz="0 0 -0.0375"/>
      <material name="red">
        <color rgba="1 0 0 .5"/>
      </material>
    </visual>
    <collision>
      <origin rpy="0 0 0" xyz="0 0 -0.0375"/>
      <geometry>
        <box size="0.075 0.075 0.075"/>
      </geometry>
    </collision>
    <inertial>
      <mass value="0.5"/>
      <inertia ixx="0.1" ixy="0.0" ixz="0.0" iyy="0.1" iyz="0.0" izz="0.1"/>
    </inertial>
  </link>
  <link name="lf_speed">
    <visual>
      <geometry>
        <cylinder length=".04" radius="0.0675"/>
      </geometry>
      <origin rpy="1.5707963267948966 0 0" xyz="0 0 0"/>
      <material name="black">
        <color rgba="0 0 0 1"/>
      </material>
    </visual>
    <collision>
      <origin rpy="1.5707963267948966 0 0" xyz="0 0 0"/>
      <geometry>
        <cylinder length=".04" radius="0.0675"/>
      </geometry>
    </collision>
    <inertial>
      <mass value="0.5"/>
      <inertia ixx="0.1" ixy="0.0" ixz="0.0" iyy="0.1" iyz="0.0" izz="0.1"/>
    </inertial>
  </link>
  <joint name="base_to_lf_angle" type="continuous">
    <parent link="base_plate"/>
    <child link="lf_angle"/>
    <origin rpy="0 0 0" xyz="0.3375 0.3375 -0.075"/>
    <axis xyz="0 0 1"/>
  </joint>
  <joint name="lf_angle_to_speed" type="continuous">
    <parent link="lf_angle"/>
    <child link="lf_speed"/>
    <origin rpy="0 0 0" xyz="0 0 -0.0675"/>
    <axis xyz="0 1 0"/>
  </joint>
  <link name="rf_angle">
    <visual>
      <geometry>
        <box size="0.075 0.075 0.075"/>
      </geometry>
      <origin rpy="0 0 0" xyz="0 0 -0.0375"/>
      <material name="red">
        <color rgba="1 0 0 .5"/>
      </material>
    </visual>
    <collision>
      <origin rpy="0 0 0" xyz="0 0 -0.0375"/>
      <geometry>
        <box size="0.075 0.075 0.075"/>
      </geometry>
    </collision>
    <inertial>
      <mass value="0.5"/>
      <inertia ixx="0.1" ixy="0.0" ixz="0.0" iyy="0.1" iyz="0.0" izz="0.1"/>
    </inertial>
  </link>
  <link name="rf_speed">
    <visual>
      <geometry>
        <cylinder length=".04" radius="0.0675"/>
      </geometry>
      <origin rpy="1.5707963267948966 0 0" xyz="0 0 0"/>
      <material name="black">
        <color rgba="0 0 0 1"/>
      </material>
    </visual>
    <collision>
      <origin rpy="1.5707963267948966 0 0" xyz="0 0 0"/>
      <geometry>
        <cylinder length=".04" radius="0.0675"/>
      </geometry>
    </collision>
    <inertial>
      <mass value="0.5"/>
      <inertia ixx="0.1" ixy="0.0" ixz="0.0" iyy="0.1" iyz="0.0" izz="0.1"/>
    </inertial>
  </link>
  <joint name="base_to_rf_angle" type="continuous">
    <parent link="base_plate"/>
    <child link="rf_angle"/>
    <origin rpy="0 0 0" xyz="0.3375 -0.3375 -0.075"/>
    <axis xyz="0 0 1"/>
  </joint>
  <joint name="rf_angle_to_speed" type="continuous">
    <parent link="rf_angle"/>
    <child link="rf_speed"/>
    <origin rpy="0 0 0" xyz="0 0 -0.0675"/>
    <axis xyz="0 1 0"/>
  </joint>
  <link name="lr_angle">
    <visual>
      <geometry>
        <box size="0.075 0.075 0.075"/>
      </geometry>
      <origin rpy="0 0 0" xyz="0 0 -0.0375"/>
      <material name="red">
        <color rgba="1 0 0 .5"/>
      </material>
    </visual>
    <collision>
      <origin rpy="0 0 0" xyz="0 0 -0.0375"/>
      <geometry>
        <box size="0.075 0.075 0.075"/>
      </geometry>
    </collision>
    <inertial>
      <mass value="0.5"/>
      <inertia ixx="0.1" ixy="0.0" ixz="0.0" iyy="0.1" iyz="0.0" izz="0.1"/>
    </inertial>
  </link>
  <link name="lr_speed">
    <visual>
      <geometry>
        <cylinder length=".04" radius="0.0675"/>
      </geometry>
      <origin rpy="1.5707963267948966 0 0" xyz="0 0 0"/>
      <material name="black">
        <color rgba="0 0 0 1"/>
      </material>
    </visual>
    <collision>
      <origin rpy="1.5707963267948966 0 0" xyz="0 0 0"/>
      <geometry>
        <cylinder length=".04" radius="0.0675"/>
      </geometry>
    </collision>
    <inertial>
      <mass value="0.5"/>
      <inertia ixx="0.1" ixy="0.0" ixz="0.0" iyy="0.1" iyz="0.0" izz="0.1"/>
    </inertial>
  </link>
  <joint name="base_to_lr_angle" type="continuous">
    <parent link="base_plate"/>
    <child link="lr_angle"/>
    <origin rpy="0 0 0" xyz="-0.3375 0.3375 -0.075"/>
    <axis xyz="0 0 1"/>
  </joint>
  <joint name="lr_angle_to_speed" type="continuous">
    <parent link="lr_angle"/>
    <child link="lr_speed"/>
    <origin rpy="0 0 0" xyz="0 0 -0.0675"/>
    <axis xyz="0 1 0"/>
  </joint>
  <link name="rr_angle">
    <visual>
      <geometry>
        <box size="0.075 0.075 0.075"/>
      </geometry>
      <origin rpy="0 0 0" xyz="0 0 -0.0375"/>
      <material name="red">
        <color rgba="1 0 0 .5"/>
      </material>
    </visual>
    <collision>
      <origin rpy="0 0 0" xyz="0 0 -0.0375"/>
      <geometry>
        <box size="0.075 0.075 0.075"/>
      </geometry>
    </collision>
    <inertial>
      <mass value="0.5"/>
      <inertia ixx="0.1" ixy="0.0" ixz="0.0" iyy="0.1" iyz="0.0" izz="0.1"/>
    </inertial>
  </link>
  <link name="rr_speed">
    <visual>
      <geometry>
        <cylinder length=".04" radius="0.0675"/>
      </geometry>
      <origin rpy="1.5707963267948966 0 0" xyz="0 0 0"/>
      <material name="black">
        <color rgba="0 0 0 1"/>
      </material>
    </visual>
    <collision>
      <origin rpy="1.5707963267948966 0 0" xyz="0 0 0"/>
      <geometry>
        <cylinder length=".04" radius="0.0675"/>
      </geometry>
    </collision>
    <inertial>
      <mass value="0.5"/>
      <inertia ixx="0.1" ixy="0.0" ixz="0.0" iyy="0.1" iyz="0.0" izz="0.1"/>
    </inertial>
  </link>
  <joint name="base_to_rr_angle" type="continuous">
    <parent link="base_plate"/>
    <child link="rr_angle"/>
    <origin rpy="0 0 0" xyz="-0.3375 -0.3375 -0.075"/>
    <axis xyz="0 0 1"/>
  </joint>
  <joint name="rr_angle_to_speed" type="continuous">
    <parent link="rr_angle"/>
    <child link="rr_speed"/>
    <origin rpy="0 0 0" xyz="0 0 -0.0675"/>
    <axis xyz="0 1 0"/>
  </joint>
  <!--	<xacro:include filename="$(find controller_node)/urdf/2019_compbot.urdf"/>-->
</robot>

