<robot name="onshape">
<link name="chassis">
<visual>
<origin xyz="0.0225928 0.0168899 0.0252748" rpy="0 -0 0" />
<geometry>
<mesh filename="package://chassis.stl"/>
</geometry>
<material name="chassis_material">
<color rgba="0.615686 0.811765 0.929412 1.0"/>
</material>
</visual>
<collision>
<origin xyz="0.0225928 0.0168899 0.0252748" rpy="0 -0 0" />
<geometry>
<mesh filename="package://chassis.stl"/>
</geometry>
<material name="chassis_material">
<color rgba="0.615686 0.811765 0.929412 1.0"/>
</material>
</collision>
<inertial>
<origin xyz="0.124193 0.0930899 0.0379748" rpy="0 0 0"/>
<mass value="10.1395" />
<inertia ixx="0.00425598" ixy="0"  ixz="0" iyy="0.00747672" iyz="0" izz="0.0115026" />
</inertial>
</link>

<link name="wheel">
<visual>
<origin xyz="0 0 -0.00635" rpy="0 -0 0" />
<geometry>
<mesh filename="package://wheel.stl"/>
</geometry>
<material name="wheel_material">
<color rgba="0.615686 0.811765 0.929412 1.0"/>
</material>
</visual>
<collision>
<origin xyz="0 0 -0.00635" rpy="0 -0 0" />
<geometry>
<mesh filename="package://wheel.stl"/>
</geometry>
<material name="wheel_material">
<color rgba="0.615686 0.811765 0.929412 1.0"/>
</material>
</collision>
<inertial>
<origin xyz="-1.67526e-18 -0.00143575 -0.003175" rpy="0 0 0"/>
<mass value="0.0319047" />
<inertia ixx="4.96715e-06" ixy="0"  ixz="0" iyy="5.7092e-06" iyz="0" izz="1.04619e-05" />
</inertial>
</link>

<joint name="rotateright" type="revolute">
<origin xyz="0.225793 0.16929 0.0379748" rpy="3.14159 1.5708 0" />
<parent link="chassis" />
<child link="wheel" />
<axis xyz="0 0 1"/>
<limit effort="1" velocity="20" />
<joint_properties friction="0.0"/>
</joint>

<link name="wheel_2">
<visual>
<origin xyz="0 0 -0.00635" rpy="0 -0 0" />
<geometry>
<mesh filename="package://wheel.stl"/>
</geometry>
<material name="wheel_material">
<color rgba="0.615686 0.811765 0.929412 1.0"/>
</material>
</visual>
<collision>
<origin xyz="0 0 -0.00635" rpy="0 -0 0" />
<geometry>
<mesh filename="package://wheel.stl"/>
</geometry>
<material name="wheel_material">
<color rgba="0.615686 0.811765 0.929412 1.0"/>
</material>
</collision>
<inertial>
<origin xyz="-1.67526e-18 -0.00143575 -0.003175" rpy="0 0 0"/>
<mass value="0.0319047" />
<inertia ixx="4.96715e-06" ixy="0"  ixz="0" iyy="5.7092e-06" iyz="0" izz="1.04619e-05" />
</inertial>
</link>

<joint name="rotateleft" type="revolute">
<origin xyz="0.0225928 0.16929 0.0379748" rpy="-3.14159 -1.5708 0" />
<parent link="chassis" />
<child link="wheel_2" />
<axis xyz="0 0 1"/>
<limit effort="1" velocity="20" />
<joint_properties friction="0.0"/>
</joint>

<link name="wheel_3">
<visual>
<origin xyz="0 -3.46945e-18 -0.00635" rpy="0 -0 0" />
<geometry>
<mesh filename="package://wheel.stl"/>
</geometry>
<material name="wheel_material">
<color rgba="0.615686 0.811765 0.929412 1.0"/>
</material>
</visual>
<collision>
<origin xyz="0 -3.46945e-18 -0.00635" rpy="0 -0 0" />
<geometry>
<mesh filename="package://wheel.stl"/>
</geometry>
<material name="wheel_material">
<color rgba="0.615686 0.811765 0.929412 1.0"/>
</material>
</collision>
<inertial>
<origin xyz="-1.67526e-18 -0.00143575 -0.003175" rpy="0 0 0"/>
<mass value="0.0319047" />
<inertia ixx="4.96715e-06" ixy="0"  ixz="0" iyy="5.7092e-06" iyz="0" izz="1.04619e-05" />
</inertial>
</link>

<joint name="casterright" type="revolute">
<origin xyz="0.225793 0.0168899 0.0379748" rpy="3.14159 1.5708 0" />
<parent link="chassis" />
<child link="wheel_3" />
<axis xyz="0 0 1"/>
<limit effort="1" velocity="20" />
<joint_properties friction="0.0"/>
</joint>

<link name="wheel_4">
<visual>
<origin xyz="0 0 -0.00635" rpy="0 -0 0" />
<geometry>
<mesh filename="package://wheel.stl"/>
</geometry>
<material name="wheel_material">
<color rgba="0.615686 0.811765 0.929412 1.0"/>
</material>
</visual>
<collision>
<origin xyz="0 0 -0.00635" rpy="0 -0 0" />
<geometry>
<mesh filename="package://wheel.stl"/>
</geometry>
<material name="wheel_material">
<color rgba="0.615686 0.811765 0.929412 1.0"/>
</material>
</collision>
<inertial>
<origin xyz="-1.67526e-18 -0.00143575 -0.003175" rpy="0 0 0"/>
<mass value="0.0319047" />
<inertia ixx="4.96715e-06" ixy="0"  ixz="0" iyy="5.7092e-06" iyz="0" izz="1.04619e-05" />
</inertial>
</link>

<joint name="casterleft" type="revolute">
<origin xyz="0.0225928 0.0168899 0.0379748" rpy="-3.14159 -1.5708 0" />
<parent link="chassis" />
<child link="wheel_4" />
<axis xyz="0 0 1"/>
<limit effort="1" velocity="20" />
<joint_properties friction="0.0"/>
</joint>


</robot>
